Workbook

Sheet README
A1: Joint-production equilibrium displacement model for animal-product markets
A2: Version 2026-10-17. Companion workbook to the paper 'Elasticity and joint production in animal-product markets'.
A4: WHAT IT DOES
A5: For each animal (dairy cow, fed steer, layer hen, broiler, hog, Alaska pollock, farmed salmon) the workbook lists the products of one animal unit, their prices and value shares,
A6: and computes for each product the displacement factor DF: the share of a demand reduction in that product (e.g. by a novel ingredient) that shows up as fewer animals produced,
A7: in the short run and the long run. It also computes the price fall of the product, the floor price (next-best use) for by-products, and the animal reduction if the product were fully replaced.
A9: HOW TO USE
A10: 1. Assumptions sheet: supply elasticities per animal (short run, long run) and the size of the demand shift. Blue cells are inputs.
A11: 2. Branch sheets (Dairy, Beef, Eggs, Broiler, Pork, Pollock, Salmon): inputs block (yields, prices, allowances; blue), then table A (products), table B (streams: edit demand elasticities and floor ratios), table C (routes: raw-volume shares of fungible routes), table D (aggregates).
A12: 3. Summary sheet: all products side by side, linked (green) to the branch sheets, with three horizons (within a year, 3-5 years, constant-cost limit). Sensitivity sheet: the single-product formula across elasticities, and a target calculator. Exit sheet: price-cap (perfect substitute) scenarios from the exact non-linear model. Ranges sheet: Monte Carlo 10th-90th percentiles over the elasticity ranges. The Exit and Ranges sheets are computed in the companion Python model and pasted as values.
A13: 4. Dairy and Eggs have a scenario selector (yellow cell) switching between two price years, because by-product value shares move a lot with prices.
A14: Colour legend: blue = hard-coded input you can edit; black = formula; green = link to another sheet; yellow fill = scenario selector.
... A27: Prices are a snapshot (date stated on each sheet). Value shares, and therefore DF, change with relative prices; this is a feature of the problem, not a bug of the workbook.

Sheet Summary
A1: Summary: displacement factors and floors by product (linked to branch sheets)
A2: DF = share of a demand reduction in the product that becomes a reduction in animals produced, at three horizons (within a year; 3-5 years; constant-cost limit, where supply is perfectly elastic). 1 - DF = the total discount, the elasticity discount 1/(1+eps_s*H) and the joint-production discount together; DF(3-5 years)/DF(limit) is the bundle factor, so 1 - that ratio is the elasticity discount alone. Floor = next-best use as a share of the current price.
A4: Branch | B4: Product | C4: Share of animal value | D4: Demand elasticity (stream) | E4: DF short run (within a year) | F4: DF long run (3-5 years) | G4: DF constant-cost limit | H4: Total discount (1-DF, 3-5 years) | I4: Stream price change for a 10% replacement | J4: Animal change if fully replaced (LR, linear, floor-capped) | K4: Floor ratio (P_floor/P_now) | L4: Biotech route most likely to target it | M4: Technical reachability | N4: Animal mass per kg product (LR) | O4: Reading
A5: Dairy | B5: =Dairy!A49 -> Fluid milk (Class I) | C5: =Dairy!I49 -> 0.17438161 | D5: =INDEX(Dairy!$F$65:$F$73,MATCH(Dairy!B49,Dairy!$A$65:$A$73,0)) -> -0.4 | E5: =Dairy!L49 -> 0.026935892 | F5: =Dairy!M49 -> 0.10128844 | G5: =Dairy!N49 -> 0.17605264 | H5: =1-F5 -> 0.89871156 | I5: =Dairy!Q49 -> -0.013420291 | J5: =Dairy!T49 -> -0.10128844 | K5: =INDEX(Dairy!$G$65:$G$73,MATCH(Dairy!B49,Dairy!$A$65:$A$73,0)) -> 0 | L5: Precision fermentation (whey+casein) / plant-based milks | M5: Medium | N5: =Dairy!U49 -> 53.309705 | O5: =IF(F5>=0.2,"primary product: displacement is a fifth or more of the replaced volume",IF(F5>=0.05,"co-product: a twentieth to a fifth","by-product or quota-limited: under a twentieth; price falls toward the floor instead")) -> co-product: a twentieth to a fifth
A6: Dairy | B6: =Dairy!A50 -> Other dairy: yogurt, ice cream, etc. (Class II) | C6: =Dairy!I50 -> 0.068445951 | D6: =INDEX(Dairy!$F$65:$F$73,MATCH(Dairy!B50,Dairy!$A$65:$A$73,0)) -> -0.9 | E6: =Dairy!L50 -> 0.011341428 | F6: =Dairy!M50 -> 0.042647764 | G6: =Dairy!N50 -> 0.074127425 | H6: =1-F6 -> 0.95735224 | I6: =Dairy!Q50 -> -0.0056506489 | J6: =Dairy!T50 -> -0.042647764 | K6: =INDEX(Dairy!$G$65:$G$73,MATCH(Dairy!B50,Dairy!$A$65:$A$73,0)) -> 0 | L6: Plant-based / PF casein and whey | M6: Medium | N6: =Dairy!U50 -> 53.309705 | O6: =IF(F6>=0.2,"primary product: displacement is a fifth or more of the replaced volume",IF(F6>=0.05,"co-product: a twentieth to a fifth","by-product or quota-limited: under a twentieth; price falls toward the floor instead")) -> by-product or quota-limited: under a twentieth; price falls toward the floor instead
A7: Dairy | B7: =Dairy!A51 -> Butter / cream (3.5 lb fat per cwt) | C7: =Dairy!I51 -> 0.032651392 | D7: =INDEX(Dairy!$F$65:$F$73,MATCH(Dairy!B51,Dairy!$A$65:$A$73,0)) -> -0.6 | E7: =Dairy!L51 -> 0.0070910188 | F7: =Dairy!M51 -> 0.026664727 | G7: =Dairy!N51 -> 0.046346804 | H7: =1-F7 -> 0.97333527 | I7: =Dairy!Q51 -> -0.1075224 | J7: =Dairy!T51 -> -0.026664727 | K7: =INDEX(Dairy!$G$65:$G$73,MATCH(Dairy!B51,Dairy!$A$65:$A$73,0)) -> 0 | L7: Plant oils; fermentation-derived fats | M7: High | N7: =Dairy!U51 -> 20.511329 | O7: =IF(F7>=0.2,"primary product: displacement is a fifth or more of the replaced volume",IF(F7>=0.05,"co-product: a twentieth to a fifth","by-product or quota-limited: under a twentieth; price falls toward the floor instead")) -> by-product or quota-limited: under a twentieth; price falls toward the floor instead
A8: Dairy | B8: =Dairy!A52 -> Nonfat dry milk / SMP (also the casein route) | C8: =Dairy!I52 -> 0.087017981 | D8: =INDEX(Dairy!$F$65:$F$73,MATCH(Dairy!B52,Dairy!$A$65:$A$73,0)) -> -1 | E8: =Dairy!L52 -> 0.011338802 | F8: =Dairy!M52 -> 0.04263789 | G8: =Dairy!N52 -> 0.074110262 | H8: =1-F8 -> 0.95736211 | I8: =Dairy!Q52 -> -0.043255676 | J8: =Dairy!T52 -> -0.029548544 | K8: =INDEX(Dairy!$G$65:$G$73,MATCH(Dairy!B52,Dairy!$A$65:$A$73,0)) -> 0.6 | L8: PF casein + lactose blends | M8: Medium | N8: =Dairy!U52 -> 32.798377 | O8: =IF(F8>=0.2,"primary product: displacement is a fifth or more of the replaced volume",IF(F8>=0.05,"co-product: a twentieth to a fifth","by-product or quota-limited: under a twentieth; price falls toward the floor instead")) -> by-product or quota-limited: under a twentieth; price falls toward the floor instead
A9: Dairy | B9: =Dairy!A53 -> Cheese (cheddar-equivalent) | C9: =Dairy!I53 -> 0.40371872 | D9: =INDEX(Dairy!$F$65:$F$73,MATCH(Dairy!B53,Dairy!$A$65:$A$73,0)) -> -0.55 | E9: =Dairy!L53 -> 0.074960437 | F9: =Dairy!M53 -> 0.28187764 | G9: =Dairy!N53 -> 0.48994042 | H9: =1-F9 -> 0.71812236 | I9: =Dairy!Q53 -> -0.067202523 | J9: =Dairy!T53 -> -0.28187764 | K9: =INDEX(Dairy!$G$65:$G$73,MATCH(Dairy!B53,Dairy!$A$65:$A$73,0)) -> 0 | L9: PF casein (micelle-forming) + plant fats | M9: Low-medium | N9: =Dairy!U53 -> 4.4320384 | O9: =IF(F9>=0.2,"primary product: displacement is a fifth or more of the replaced volume",IF(F9>=0.05,"co-product: a twentieth to a fifth","by-product or quota-limited: under a twentieth; price falls toward the floor instead")) -> primary product: displacement is a fifth or more of the replaced volume
A10: Dairy | B10: =Dairy!A54 -> WPC 80 (whey protein concentrate) | C10: =Dairy!I54 -> 0.069389027 | D10: =INDEX(Dairy!$F$65:$F$73,MATCH(Dairy!B54,Dairy!$A$65:$A$73,0)) -> -1.5 | E10: =Dairy!L54 -> 0.0047240605 | F10: =Dairy!M54 -> 0.017764131 | G10: =Dairy!N54 -> 0.030876397 | H10: =1-F10 -> 0.98223587 | I10: =Dairy!Q54 -> -0.034043237 | J10: =Dairy!T54 -> -0.017764131 | K10: =INDEX(Dairy!$G$65:$G$73,MATCH(Dairy!B54,Dairy!$A$65:$A$73,0)) -> 0.06 | L10: PF beta-lactoglobulin | M10: High | N10: =Dairy!U54 -> 9.9560774 | O10: =IF(F10>=0.2,"primary product: displacement is a fifth or more of the replaced volume",IF(F10>=0.05,"co-product: a twentieth to a fifth","by-product or quota-limited: under a twentieth; price falls toward the floor instead")) -> by-product or quota-limited: under a twentieth; price falls toward the floor instead
A11: Dairy | B11: =Dairy!A55 -> WPI (whey protein isolate) | C11: =Dairy!I55 -> 0.056686664 | D11: =INDEX(Dairy!$F$65:$F$73,MATCH(Dairy!B55,Dairy!$A$65:$A$73,0)) -> -1.5 | E11: =Dairy!L55 -> 0.0038592735 | F11: =Dairy!M55 -> 0.014512227 | G11: =Dairy!N55 -> 0.02522416 | H11: =1-F11 -> 0.98548777 | I11: =Dairy!Q55 -> -0.027811278 | J11: =Dairy!T55 -> -0.014512227 | K11: =INDEX(Dairy!$G$65:$G$73,MATCH(Dairy!B55,Dairy!$A$65:$A$73,0)) -> 0.06 | L11: PF beta-lactoglobulin | M11: High | N11: =Dairy!U55 -> 14.311861 | O11: =IF(F11>=0.2,"primary product: displacement is a fifth or more of the replaced volume",IF(F11>=0.05,"co-product: a twentieth to a fifth","by-product or quota-limited: under a twentieth; price falls toward the floor instead")) -> by-product or quota-limited: under a twentieth; price falls toward the floor instead
A12: Dairy | B12: =Dairy!A56 -> Dry whey (sweet whey powder) | C12: =Dairy!I56 -> 0.007045655 | D12: =INDEX(Dairy!$F$65:$F$73,MATCH(Dairy!B56,Dairy!$A$65:$A$73,0)) -> -2 | E12: =Dairy!L56 -> 0.00035975538 | F12: =Dairy!M56 -> 0.0013528069 | G12: =Dairy!N56 -> 0.0023513564 | H12: =1-F12 -> 0.99864719 | I12: =Dairy!Q56 -> -0.011706647 | J12: =Dairy!T56 -> -0.0013528069 | K12: =INDEX(Dairy!$G$65:$G$73,MATCH(Dairy!B56,Dairy!$A$65:$A$73,0)) -> 0.5 | L12: none economic (floor-priced) | M12: n/a | N12: =Dairy!U56 -> 0.3757797 | O12: =IF(F12>=0.2,"primary product: displacement is a fifth or more of the replaced volume",IF(F12>=0.05,"co-product: a twentieth to a fifth","by-product or quota-limited: under a twentieth; price falls toward the floor instead")) -> by-product or quota-limited: under a twentieth; price falls toward the floor instead
A13: Dairy | B13: =Dairy!A57 -> Lactose | C13: =Dairy!I57 -> 0.011287748 | D13: =INDEX(Dairy!$F$65:$F$73,MATCH(Dairy!B57,Dairy!$A$65:$A$73,0)) -> -2 | E13: =Dairy!L57 -> 0.00057635921 | F13: =Dairy!M57 -> 0.0021673136 | G13: =Dairy!N57 -> 0.0037670762 | H13: =1-F13 -> 0.99783269 | I13: =Dairy!Q57 -> -0.018755061 | J13: =Dairy!T57 -> -0.0021673136 | K13: =INDEX(Dairy!$G$65:$G$73,MATCH(Dairy!B57,Dairy!$A$65:$A$73,0)) -> 0.5 | L13: none (floor-priced) | M13: n/a | N13: =Dairy!U57 -> 0.40135437 | O13: =IF(F13>=0.2,"primary product: displacement is a fifth or more of the replaced volume",IF(F13>=0.05,"co-product: a twentieth to a fifth","by-product or quota-limited: under a twentieth; price falls toward the floor instead")) -> by-product or quota-limited: under a twentieth; price falls toward the floor instead
A14: Dairy | B14: =Dairy!A58 -> Permeate / condensed whey / feed | C14: =Dairy!I58 -> 0.01137525 | D14: =INDEX(Dairy!$F$65:$F$73,MATCH(Dairy!B58,Dairy!$A$65:$A$73,0)) -> -2 | E14: =Dairy!L58 -> 0.00058082711 | F14: =Dairy!M58 -> 0.0021841145 | G14: =Dairy!N58 -> 0.0037962783 | H14: =1-F14 -> 0.99781589 | I14: =Dairy!Q58 -> -0.018900449 | J14: =Dairy!T58 -> -0.0021841145 | K14: =INDEX(Dairy!$G$65:$G$73,MATCH(Dairy!B58,Dairy!$A$65:$A$73,0)) -> 0.5 | L14: none | M14: n/a | N14: =Dairy!U58 -> 0.24267939 | O14: =IF(F14>=0.2,"primary product: displacement is a fifth or more of the replaced volume",IF(F14>=0.05,"co-product: a twentieth to a fifth","by-product or quota-limited: under a twentieth; price falls toward the floor instead")) -> by-product or quota-limited: under a twentieth; price falls toward the floor instead
A15: Dairy | B15: =Dairy!A59 -> Cull cows (manufacturing beef) | C15: =Dairy!I59 -> 0.0468 | D15: =INDEX(Dairy!$F$65:$F$73,MATCH(Dairy!B59,Dairy!$A$65:$A$73,0)) -> -0.8 | E15: =Dairy!L59 -> 0.0059459464 | F15: =Dairy!M59 -> 0.022358852 | G15: =Dairy!N59 -> 0.038862627 | H15: =1-F15 -> 0.97764115 | I15: =Dairy!Q59 -> -0.12220514 | J15: =Dairy!T59 -> -0.017624635 | K15: =INDEX(Dairy!$G$65:$G$73,MATCH(Dairy!B59,Dairy!$A$65:$A$73,0)) -> 0.15 | L15: Plant-based / mycoprotein mince, blends | M15: High | N15: =Dairy!U59 -> 2.2358852 | O15: =IF(F15>=0.2,"primary product: displacement is a fifth or more of the replaced volume",IF(F15>=0.05,"co-product: a twentieth to a fifth","by-product or quota-limited: under a twentieth; price falls toward the floor instead")) -> by-product or quota-limited: under a twentieth; price falls toward the floor instead
A16: Dairy | B16: =Dairy!A60 -> Calves (beef-on-dairy, bull calves) | C16: =Dairy!I60 -> 0.0312 | D16: =INDEX(Dairy!$F$65:$F$73,MATCH(Dairy!B60,Dairy!$A$65:$A$73,0)) -> -0.6 | E16: =Dairy!L60 -> 0.0052852857 | F16: =Dairy!M60 -> 0.019874535 | G16: =Dairy!N60 -> 0.034544557 | H16: =1-F16 -> 0.98012546 | I16: =Dairy!Q60 -> -0.16335424 | J16: =Dairy!T60 -> -0.016698759 | K16: =INDEX(Dairy!$G$65:$G$73,MATCH(Dairy!B60,Dairy!$A$65:$A$73,0)) -> 0.05 | L16: n/a | M16: n/a | N16: =Dairy!U60 -> 1.9874535 | O16: =IF(F16>=0.2,"primary product: displacement is a fifth or more of the replaced volume",IF(F16>=0.05,"co-product: a twentieth to a fifth","by-product or quota-limited: under a twentieth; price falls toward the floor instead")) -> by-product or quota-limited: under a twentieth; price falls toward the floor instead
A18: Beef | B18: =Beef!A42 -> Middle meats: steaks and roasts from rib and loin | C18: =Beef!I42 -> 0.43407997 | D18: =INDEX(Beef!$F$54:$F$57,MATCH(Beef!B42,Beef!$A$54:$A$57,0)) -> -1 | E18: =Beef!L42 -> 0.056353981 | F18: =Beef!M42 -> 0.18988031 | G18: =Beef!N42 -> 0.41896718 | H18: =1-F18 -> 0.81011969 | I18: =Beef!Q42 -> -0.081011969 | J18: =Beef!T42 -> -0.18988031 | K18: =INDEX(Beef!$G$54:$G$57,MATCH(Beef!B42,Beef!$A$54:$A$57,0)) -> 0 | L18: Cultivated / mycoprotein whole-cut | M18: Low | N18: =Beef!U42 -> 0.92283317 | O18: =IF(F18>=0.2,"primary product: displacement is a fifth or more of the replaced volume",IF(F18>=0.05,"co-product: a twentieth to a fifth","by-product or quota-limited: under a twentieth; price falls toward the floor instead")) -> co-product: a twentieth to a fifth
A19: Beef | B19: =Beef!A43 -> End-meat whole-muscle cuts (chuck/round roasts, steaks; 50% of chuck+round) | C19: =Beef!I43 -> 0.21875927 | D19: =INDEX(Beef!$F$54:$F$57,MATCH(Beef!B43,Beef!$A$54:$A$57,0)) -> -0.9 | E19: =Beef!L43 -> 0.031555773 | F19: =Beef!M43 -> 0.10632469 | G19: =Beef!N43 -> 0.23460336 | H19: =1-F19 -> 0.89367531 | I19: =Beef!Q43 -> -0.081792744 | J19: =Beef!T43 -> -0.10632469 | K19: =INDEX(Beef!$G$54:$G$57,MATCH(Beef!B43,Beef!$A$54:$A$57,0)) -> 0 | L19: Cultivated / plant-based whole-cut | M19: Low | N19: =Beef!U43 -> 0.64986275 | O19: =IF(F19>=0.2,"primary product: displacement is a fifth or more of the replaced volume",IF(F19>=0.05,"co-product: a twentieth to a fifth","by-product or quota-limited: under a twentieth; price falls toward the floor instead")) -> co-product: a twentieth to a fifth
A20: Beef | B20: =Beef!A44 -> Thin-meat whole-muscle (brisket, flank, skirt; 40% of thin meats) | C20: =Beef!I44 -> 0.040908165 | D20: =INDEX(Beef!$F$54:$F$57,MATCH(Beef!B44,Beef!$A$54:$A$57,0)) -> -0.9 | E20: =Beef!L44 -> 0.0059009557 | F20: =Beef!M44 -> 0.019882806 | G20: =Beef!N44 -> 0.043871023 | H20: =1-F20 -> 0.98011719 | I20: =Beef!Q44 -> -0.015295311 | J20: =Beef!T44 -> -0.019882806 | K20: =INDEX(Beef!$G$54:$G$57,MATCH(Beef!B44,Beef!$A$54:$A$57,0)) -> 0 | L20: Plant-based whole-cut | M20: Low | N20: =Beef!U44 -> 0.51233782 | O20: =IF(F20>=0.2,"primary product: displacement is a fifth or more of the replaced volume",IF(F20>=0.05,"co-product: a twentieth to a fifth","by-product or quota-limited: under a twentieth; price falls toward the floor instead")) -> by-product or quota-limited: under a twentieth; price falls toward the floor instead
A21: Beef | B21: =Beef!A45 -> Grinding material: trim and ground chuck/round (minced beef) | C21: =Beef!I45 -> 0.24594768 | D21: =INDEX(Beef!$F$54:$F$57,MATCH(Beef!B45,Beef!$A$54:$A$57,0)) -> -0.85 | E21: =Beef!L45 -> 0.037564592 | F21: =Beef!M45 -> 0.12657094 | G21: =Beef!N45 -> 0.27927629 | H21: =1-F21 -> 0.87342906 | I21: =Beef!Q45 -> -0.10275636 | J21: =Beef!T45 -> -0.087353332 | K21: =INDEX(Beef!$G$54:$G$57,MATCH(Beef!B45,Beef!$A$54:$A$57,0)) -> 0.3 | L21: Plant-based / mycoprotein mince, blends, cultivated fat | M21: High | N21: =Beef!U45 -> 0.57059429 | O21: =IF(F21>=0.2,"primary product: displacement is a fifth or more of the replaced volume",IF(F21>=0.05,"co-product: a twentieth to a fifth","by-product or quota-limited: under a twentieth; price falls toward the floor instead")) -> co-product: a twentieth to a fifth
A22: Beef | B22: =Beef!A46 -> Hide | C22: =Beef!I46 -> 0.0069797358 | D22: =INDEX(Beef!$F$54:$F$57,MATCH(Beef!B46,Beef!$A$54:$A$57,0)) -> -2.5 | E22: =Beef!L46 -> 0.00036245479 | F22: =Beef!M46 -> 0.0012212629 | G22: =Beef!N46 -> 0.0026946927 | H22: =1-F22 -> 0.99877874 | I22: =Beef!Q46 -> -0.0045807791 | J22: =Beef!T46 -> -0.0012212629 | K22: =INDEX(Beef!$G$54:$G$57,MATCH(Beef!B46,Beef!$A$54:$A$57,0)) -> 0.4 | L22: Mycelium / bio-based leather | M22: High | N22: =Beef!U46 -> 1.709768 | O22: =IF(F22>=0.2,"primary product: displacement is a fifth or more of the replaced volume",IF(F22>=0.05,"co-product: a twentieth to a fifth","by-product or quota-limited: under a twentieth; price falls toward the floor instead")) -> by-product or quota-limited: under a twentieth; price falls toward the floor instead
A23: Beef | B23: =Beef!A47 -> Tallow and technical fat | C23: =Beef!I47 -> 0.015395303 | D23: =INDEX(Beef!$F$54:$F$57,MATCH(Beef!B47,Beef!$A$54:$A$57,0)) -> -2.5 | E23: =Beef!L47 -> 0.0007994717 | F23: =Beef!M47 -> 0.002693757 | G23: =Beef!N47 -> 0.0059437221 | H23: =1-F23 -> 0.99730624 | I23: =Beef!Q47 -> -0.01010389 | J23: =Beef!T47 -> -0.002693757 | K23: =INDEX(Beef!$G$54:$G$57,MATCH(Beef!B47,Beef!$A$54:$A$57,0)) -> 0.4 | L23: Oleochemicals / fermentation fats | M23: High | N23: =Beef!U47 -> 3.7712598 | O23: =IF(F23>=0.2,"primary product: displacement is a fifth or more of the replaced volume",IF(F23>=0.05,"co-product: a twentieth to a fifth","by-product or quota-limited: under a twentieth; price falls toward the floor instead")) -> by-product or quota-limited: under a twentieth; price falls toward the floor instead
A24: Beef | B24: =Beef!A48 -> Edible offal (tongue, cheek, oxtail, liver, tripe, hearts, lips) | C24: =Beef!I48 -> 0.032425858 | D24: =INDEX(Beef!$F$54:$F$57,MATCH(Beef!B48,Beef!$A$54:$A$57,0)) -> -2.5 | E24: =Beef!L48 -> 0.0016838614 | F24: =Beef!M48 -> 0.0056736385 | G24: =Beef!N48 -> 0.012518772 | H24: =1-F24 -> 0.99432636 | I24: =Beef!Q48 -> -0.021280991 | J24: =Beef!T48 -> -0.0056736385 | K24: =INDEX(Beef!$G$54:$G$57,MATCH(Beef!B48,Beef!$A$54:$A$57,0)) -> 0.4 | L24: n/a | M24: Low | N24: =Beef!U48 -> 7.9430938 | O24: =IF(F24>=0.2,"primary product: displacement is a fifth or more of the replaced volume",IF(F24>=0.05,"co-product: a twentieth to a fifth","by-product or quota-limited: under a twentieth; price falls toward the floor instead")) -> by-product or quota-limited: under a twentieth; price falls toward the floor instead
A25: Beef | B25: =Beef!A49 -> Meat & bone meal, blood meal | C25: =Beef!I49 -> 0.0055040202 | D25: =INDEX(Beef!$F$54:$F$57,MATCH(Beef!B49,Beef!$A$54:$A$57,0)) -> -2.5 | E25: =Beef!L49 -> 0.00028582149 | F25: =Beef!M49 -> 0.00096305302 | G25: =Beef!N49 -> 0.0021249576 | H25: =1-F25 -> 0.99903695 | I25: =Beef!Q49 -> -0.0036122715 | J25: =Beef!T49 -> -0.00096305302 | K25: =INDEX(Beef!$G$54:$G$57,MATCH(Beef!B49,Beef!$A$54:$A$57,0)) -> 0.4 | L25: SCP / insect meal | M25: High | N25: =Beef!U49 -> 1.3482742 | O25: =IF(F25>=0.2,"primary product: displacement is a fifth or more of the replaced volume",IF(F25>=0.05,"co-product: a twentieth to a fifth","by-product or quota-limited: under a twentieth; price falls toward the floor instead")) -> by-product or quota-limited: under a twentieth; price falls toward the floor instead
A27: Eggs | B27: =Eggs!A27 -> Shell eggs (table) | C27: =Eggs!I27 -> 0.82813236 | D27: =INDEX(Eggs!$F$36:$F$40,MATCH(Eggs!B27,Eggs!$A$36:$A$40,0)) -> -0.27 | E27: =Eggs!L27 -> 0.039591267 | F27: =Eggs!M27 -> 0.45780095 | G27: =Eggs!N27 -> 0.67993232 | H27: =1-F27 -> 0.54219905 | I27: =Eggs!Q27 -> -0.045836493 | J27: =Eggs!T27 -> -0.45780095 | K27: =INDEX(Eggs!$G$36:$G$40,MATCH(Eggs!B27,Eggs!$A$36:$A$40,0)) -> 0 | L27: Plant-based liquid egg; PF ovalbumin | M27: Low-medium | N27: =Eggs!U27 -> 1.009855 | O27: =IF(F27>=0.2,"primary product: displacement is a fifth or more of the replaced volume",IF(F27>=0.05,"co-product: a twentieth to a fifth","by-product or quota-limited: under a twentieth; price falls toward the floor instead")) -> primary product: displacement is a fifth or more of the replaced volume
A28: Eggs | B28: =Eggs!A28 -> Liquid/frozen whole egg | C28: =Eggs!I28 -> 0.11176372 | D28: =INDEX(Eggs!$F$36:$F$40,MATCH(Eggs!B28,Eggs!$A$36:$A$40,0)) -> -0.8 | E28: =Eggs!L28 -> 0.011923958 | F28: =Eggs!M28 -> 0.13787888 | G28: =Eggs!N28 -> 0.20477962 | H28: =1-F28 -> 0.86212112 | I28: =Eggs!Q28 -> -0.013804873 | J28: =Eggs!T28 -> -0.13696919 | K28: =INDEX(Eggs!$G$36:$G$40,MATCH(Eggs!B28,Eggs!$A$36:$A$40,0)) -> 0.5 | L28: Plant-based egg; PF ovalbumin | M28: Medium | N28: =Eggs!U28 -> 0.78283337 | O28: =IF(F28>=0.2,"primary product: displacement is a fifth or more of the replaced volume",IF(F28>=0.05,"co-product: a twentieth to a fifth","by-product or quota-limited: under a twentieth; price falls toward the floor instead")) -> co-product: a twentieth to a fifth
A29: Eggs | B29: =Eggs!A29 -> Liquid egg white (albumen): liquid, dried albumen, protein fractions | C29: =Eggs!I29 -> 0.028554545 | D29: =INDEX(Eggs!$F$36:$F$40,MATCH(Eggs!B29,Eggs!$A$36:$A$40,0)) -> -1.5 | E29: =Eggs!L29 -> 0.0025762856 | F29: =Eggs!M29 -> 0.029790055 | G29: =Eggs!N29 -> 0.044244603 | H29: =1-F29 -> 0.97020995 | I29: =Eggs!Q29 -> -0.043429941 | J29: =Eggs!T29 -> -0.027133853 | K29: =INDEX(Eggs!$G$36:$G$40,MATCH(Eggs!B29,Eggs!$A$36:$A$40,0)) -> 0.35 | L29: PF ovalbumin / albumen proteins | M29: High | N29: =Eggs!U29 -> 0.4614051 | O29: =IF(F29>=0.2,"primary product: displacement is a fifth or more of the replaced volume",IF(F29>=0.05,"co-product: a twentieth to a fifth","by-product or quota-limited: under a twentieth; price falls toward the floor instead")) -> by-product or quota-limited: under a twentieth; price falls toward the floor instead
A30: Eggs | B30: =Eggs!A30 -> Liquid egg yolk | C30: =Eggs!I30 -> 0.030523824 | D30: =INDEX(Eggs!$F$36:$F$40,MATCH(Eggs!B30,Eggs!$A$36:$A$40,0)) -> -1 | E30: =Eggs!L30 -> 0.0041309407 | F30: =Eggs!M30 -> 0.047766812 | G30: =Eggs!N30 -> 0.070943932 | H30: =1-F30 -> 0.95223319 | I30: =Eggs!Q30 -> -0.044111668 | J30: =Eggs!T30 -> -0.03784253 | K30: =INDEX(Eggs!$G$36:$G$40,MATCH(Eggs!B30,Eggs!$A$36:$A$40,0)) -> 0.5 | L30: Plant lipids / PF | M30: Low-medium | N30: =Eggs!U30 -> 1.3842153 | O30: =IF(F30>=0.2,"primary product: displacement is a fifth or more of the replaced volume",IF(F30>=0.05,"co-product: a twentieth to a fifth","by-product or quota-limited: under a twentieth; price falls toward the floor instead")) -> by-product or quota-limited: under a twentieth; price falls toward the floor instead
A31: Eggs | B31: =Eggs!A31 -> Spent hen (soup meat, rendering) | C31: =Eggs!I31 -> 0.0010255509 | D31: =INDEX(Eggs!$F$36:$F$40,MATCH(Eggs!B31,Eggs!$A$36:$A$40,0)) -> -5 | E31: =Eggs!L31 -> 5.7950093e-06 | F31: =Eggs!M31 -> 6.7008737e-05 | G31: =Eggs!N31 -> 9.9522305e-05 | H31: =1-F31 -> 0.99993299 | I31: =Eggs!Q31 -> -0.01999866 | J31: =Eggs!T31 -> -6.7008737e-05 | K31: =INDEX(Eggs!$G$36:$G$40,MATCH(Eggs!B31,Eggs!$A$36:$A$40,0)) -> 0 | L31: n/a | M31: n/a | N31: =Eggs!U31 -> 0.0025128276 | O31: =IF(F31>=0.2,"primary product: displacement is a fifth or more of the replaced volume",IF(F31>=0.05,"co-product: a twentieth to a fifth","by-product or quota-limited: under a twentieth; price falls toward the floor instead")) -> by-product or quota-limited: under a twentieth; price falls toward the floor instead
A33: Broiler | B33: =Broiler!A33 -> Boneless skinless breast (fillets, whole-muscle nuggets) | C33: =Broiler!I33 -> 0.45213967 | D33: =INDEX(Broiler!$F$45:$F$50,MATCH(Broiler!B33,Broiler!$A$45:$A$50,0)) -> -0.8 | E33: =Broiler!L33 -> 0.051240611 | F33: =Broiler!M33 -> 0.22989632 | G33: =Broiler!N33 -> 0.5488104 | H33: =1-F33 -> 0.77010368 | I33: =Broiler!Q33 -> -0.074425434 | J33: =Broiler!T33 -> -0.22989632 | K33: =INDEX(Broiler!$G$45:$G$50,MATCH(Broiler!B33,Broiler!$A$45:$A$50,0)) -> 0 | L33: Plant-based / mycoprotein / cultivated | M33: Medium | N33: =Broiler!U33 -> 1.0426137 | O33: =IF(F33>=0.2,"primary product: displacement is a fifth or more of the replaced volume",IF(F33>=0.05,"co-product: a twentieth to a fifth","by-product or quota-limited: under a twentieth; price falls toward the floor instead")) -> primary product: displacement is a fifth or more of the replaced volume
A34: Broiler | B34: =Broiler!A34 -> Tenders | C34: =Broiler!I34 -> 0.095709335 | D34: =INDEX(Broiler!$F$45:$F$50,MATCH(Broiler!B34,Broiler!$A$45:$A$50,0)) -> -0.8 | E34: =Broiler!L34 -> 0.010846659 | F34: =Broiler!M34 -> 0.048664662 | G34: =Broiler!N34 -> 0.11617268 | H34: =1-F34 -> 0.95133534 | I34: =Broiler!Q34 -> -0.015754443 | J34: =Broiler!T34 -> -0.048664662 | K34: =INDEX(Broiler!$G$45:$G$50,MATCH(Broiler!B34,Broiler!$A$45:$A$50,0)) -> 0 | L34: as breast | M34: Medium | N34: =Broiler!U34 -> 1.2166165 | O34: =IF(F34>=0.2,"primary product: displacement is a fifth or more of the replaced volume",IF(F34>=0.05,"co-product: a twentieth to a fifth","by-product or quota-limited: under a twentieth; price falls toward the floor instead")) -> by-product or quota-limited: under a twentieth; price falls toward the floor instead
A35: Broiler | B35: =Broiler!A35 -> Wings | C35: =Broiler!I35 -> 0.19935967 | D35: =INDEX(Broiler!$F$45:$F$50,MATCH(Broiler!B35,Broiler!$A$45:$A$50,0)) -> -1 | E35: =Broiler!L35 -> 0.018074612 | F35: =Broiler!M35 -> 0.081093625 | G35: =Broiler!N35 -> 0.19358737 | H35: =1-F35 -> 0.91890638 | I35: =Broiler!Q35 -> -0.091890638 | J35: =Broiler!T35 -> -0.081093625 | K35: =INDEX(Broiler!$G$45:$G$50,MATCH(Broiler!B35,Broiler!$A$45:$A$50,0)) -> 0 | L35: n/a (bone-in) | M35: Low | N35: =Broiler!U35 -> 1.0698367 | O35: =IF(F35>=0.2,"primary product: displacement is a fifth or more of the replaced volume",IF(F35>=0.05,"co-product: a twentieth to a fifth","by-product or quota-limited: under a twentieth; price falls toward the floor instead")) -> co-product: a twentieth to a fifth
A36: Broiler | B36: =Broiler!A36 -> Leg quarters / dark meat (whole legs) | C36: =Broiler!I36 -> 0.1632018 | D36: =INDEX(Broiler!$F$45:$F$50,MATCH(Broiler!B36,Broiler!$A$45:$A$50,0)) -> -1.5 | E36: =Broiler!L36 -> 0.0098642794 | F36: =Broiler!M36 -> 0.044257114 | G36: =Broiler!N36 -> 0.10565095 | H36: =1-F36 -> 0.95574289 | I36: =Broiler!Q36 -> -0.063716192 | J36: =Broiler!T36 -> -0.03923283 | K36: =INDEX(Broiler!$G$45:$G$50,MATCH(Broiler!B36,Broiler!$A$45:$A$50,0)) -> 0.25 | N36: =Broiler!U36 -> 0.19233861 | O36: =IF(F36>=0.2,"primary product: displacement is a fifth or more of the replaced volume",IF(F36>=0.05,"co-product: a twentieth to a fifth","by-product or quota-limited: under a twentieth; price falls toward the floor instead")) -> by-product or quota-limited: under a twentieth; price falls toward the floor instead
A37: Broiler | B37: =Broiler!A37 -> Backs, necks, frames -> mechanically separated chicken (MSC nuggets, hot dogs) | C37: =Broiler!I37 -> 0.020870872 | D37: =INDEX(Broiler!$F$45:$F$50,MATCH(Broiler!B37,Broiler!$A$45:$A$50,0)) -> -3 | E37: =Broiler!L37 -> 0.00063074093 | F37: =Broiler!M37 -> 0.0028298847 | G37: =Broiler!N37 -> 0.0067555241 | H37: =1-F37 -> 0.99717012 | I37: =Broiler!Q37 -> -0.033239004 | J37: =Broiler!T37 -> -0.0024782305 | K37: =INDEX(Broiler!$G$45:$G$50,MATCH(Broiler!B37,Broiler!$A$45:$A$50,0)) -> 0.5 | L37: Plant-based / mycoprotein nuggets, hot dogs | M37: High | N37: =Broiler!U37 -> 0.023387477 | O37: =IF(F37>=0.2,"primary product: displacement is a fifth or more of the replaced volume",IF(F37>=0.05,"co-product: a twentieth to a fifth","by-product or quota-limited: under a twentieth; price falls toward the floor instead")) -> by-product or quota-limited: under a twentieth; price falls toward the floor instead
A38: Broiler | B38: =Broiler!A38 -> Giblets | C38: =Broiler!I38 -> 0.016558708 | D38: =INDEX(Broiler!$F$45:$F$50,MATCH(Broiler!B38,Broiler!$A$45:$A$50,0)) -> -2 | E38: =Broiler!L38 -> 0.00075063383 | F38: =Broiler!M38 -> 0.0033677967 | G38: =Broiler!N38 -> 0.008039632 | H38: =1-F38 -> 0.9966322 | I38: =Broiler!Q38 -> -0.015216226 | J38: =Broiler!T38 -> -0.0033677967 | K38: =INDEX(Broiler!$G$45:$G$50,MATCH(Broiler!B38,Broiler!$A$45:$A$50,0)) -> 0.15 | L38: n/a | M38: n/a | N38: =Broiler!U38 -> 0.11225989 | O38: =IF(F38>=0.2,"primary product: displacement is a fifth or more of the replaced volume",IF(F38>=0.05,"co-product: a twentieth to a fifth","by-product or quota-limited: under a twentieth; price falls toward the floor instead")) -> by-product or quota-limited: under a twentieth; price falls toward the floor instead
A39: Broiler | B39: =Broiler!A39 -> Paws (export) | C39: =Broiler!I39 -> 0.037257094 | D39: =INDEX(Broiler!$F$45:$F$50,MATCH(Broiler!B39,Broiler!$A$45:$A$50,0)) -> -2 | E39: =Broiler!L39 -> 0.0016889261 | F39: =Broiler!M39 -> 0.0075775425 | G39: =Broiler!N39 -> 0.018089172 | H39: =1-F39 -> 0.99242246 | I39: =Broiler!Q39 -> -0.034236507 | J39: =Broiler!T39 -> -0.0075775425 | K39: =INDEX(Broiler!$G$45:$G$50,MATCH(Broiler!B39,Broiler!$A$45:$A$50,0)) -> 0.15 | L39: n/a | M39: n/a | N39: =Broiler!U39 -> 0.16838983 | O39: =IF(F39>=0.2,"primary product: displacement is a fifth or more of the replaced volume",IF(F39>=0.05,"co-product: a twentieth to a fifth","by-product or quota-limited: under a twentieth; price falls toward the floor instead")) -> by-product or quota-limited: under a twentieth; price falls toward the floor instead
A40: Broiler | B40: =Broiler!A40 -> Feathers, blood, viscera, heads -> rendering | C40: =Broiler!I40 -> 0.014902838 | D40: =INDEX(Broiler!$F$45:$F$50,MATCH(Broiler!B40,Broiler!$A$45:$A$50,0)) -> -5 | E40: =Broiler!L40 -> 0.00027022818 | F40: =Broiler!M40 -> 0.0012124068 | G40: =Broiler!N40 -> 0.0028942675 | H40: =1-F40 -> 0.99878759 | I40: =Broiler!Q40 -> -0.019975752 | J40: =Broiler!T40 -> -0.0012124068 | K40: =INDEX(Broiler!$G$45:$G$50,MATCH(Broiler!B40,Broiler!$A$45:$A$50,0)) -> 0 | L40: SCP / insect meal | M40: High | N40: =Broiler!U40 -> 0.0089807911 | O40: =IF(F40>=0.2,"primary product: displacement is a fifth or more of the replaced volume",IF(F40>=0.05,"co-product: a twentieth to a fifth","by-product or quota-limited: under a twentieth; price falls toward the floor instead")) -> by-product or quota-limited: under a twentieth; price falls toward the floor instead
A42: Pork | B42: =Pork!A33 -> Loin (chops, roasts) | C42: =Pork!I33 -> 0.23134818 | D42: =INDEX(Pork!$F$45:$F$49,MATCH(Pork!B33,Pork!$A$45:$A$49,0)) -> -0.9 | E42: =Pork!L33 -> 0.07144934 | F42: =Pork!M33 -> 0.14569139 | G42: =Pork!N33 -> 0.23417394 | H42: =1-F42 -> 0.85430861 | I42: =Pork!Q33 -> -0.043608931 | J42: =Pork!T33 -> -0.14569139 | K42: =INDEX(Pork!$G$45:$G$49,MATCH(Pork!B33,Pork!$A$45:$A$49,0)) -> 0 | L42: Cultivated / plant whole-cut | M42: Low | N42: =Pork!U33 -> 0.7538245 | O42: =IF(F42>=0.2,"primary product: displacement is a fifth or more of the replaced volume",IF(F42>=0.05,"co-product: a twentieth to a fifth","by-product or quota-limited: under a twentieth; price falls toward the floor instead")) -> co-product: a twentieth to a fifth
A43: Pork | B43: =Pork!A34 -> Butt (shoulder) | C43: =Pork!I34 -> 0.1184575 | D43: =INDEX(Pork!$F$45:$F$49,MATCH(Pork!B34,Pork!$A$45:$A$49,0)) -> -0.9 | E43: =Pork!L34 -> 0.036584296 | F43: =Pork!M34 -> 0.074598548 | G43: =Pork!N34 -> 0.11990438 | H43: =1-F43 -> 0.92540145 | I43: =Pork!Q34 -> -0.022329137 | J43: =Pork!T34 -> -0.074598548 | K43: =INDEX(Pork!$G$45:$G$49,MATCH(Pork!B34,Pork!$A$45:$A$49,0)) -> 0 | L43: Plant-based pulled pork | M43: Medium | N43: =Pork!U34 -> 0.95621652 | O43: =IF(F43>=0.2,"primary product: displacement is a fifth or more of the replaced volume",IF(F43>=0.05,"co-product: a twentieth to a fifth","by-product or quota-limited: under a twentieth; price falls toward the floor instead")) -> co-product: a twentieth to a fifth
A44: Pork | B44: =Pork!A35 -> Spareribs | C44: =Pork!I35 -> 0.080072271 | D44: =INDEX(Pork!$F$45:$F$49,MATCH(Pork!B35,Pork!$A$45:$A$49,0)) -> -0.9 | E44: =Pork!L35 -> 0.024729439 | F44: =Pork!M35 -> 0.050425468 | G44: =Pork!N35 -> 0.081050296 | H44: =1-F44 -> 0.94957453 | I44: =Pork!Q35 -> -0.015093553 | J44: =Pork!T35 -> -0.050425468 | K44: =INDEX(Pork!$G$45:$G$49,MATCH(Pork!B35,Pork!$A$45:$A$49,0)) -> 0 | L44: n/a (bone-in) | M44: Low | N44: =Pork!U35 -> 1.3652885 | O44: =IF(F44>=0.2,"primary product: displacement is a fifth or more of the replaced volume",IF(F44>=0.05,"co-product: a twentieth to a fifth","by-product or quota-limited: under a twentieth; price falls toward the floor instead")) -> co-product: a twentieth to a fifth
A45: Pork | B45: =Pork!A36 -> Ham (mostly cured) | C45: =Pork!I36 -> 0.22344586 | D45: =INDEX(Pork!$F$45:$F$49,MATCH(Pork!B36,Pork!$A$45:$A$49,0)) -> -0.75 | E45: =Pork!L36 -> 0.082810553 | F45: =Pork!M36 -> 0.16885789 | G45: =Pork!N36 -> 0.27141011 | H45: =1-F45 -> 0.83114211 | I45: =Pork!Q36 -> -0.11081895 | J45: =Pork!T36 -> -0.16885789 | K45: =INDEX(Pork!$G$45:$G$49,MATCH(Pork!B36,Pork!$A$45:$A$49,0)) -> 0 | L45: Plant-based deli | M45: Medium | N45: =Pork!U36 -> 0.89429828 | O45: =IF(F45>=0.2,"primary product: displacement is a fifth or more of the replaced volume",IF(F45>=0.05,"co-product: a twentieth to a fifth","by-product or quota-limited: under a twentieth; price falls toward the floor instead")) -> co-product: a twentieth to a fifth
...

Sheet Assumptions
A1: Global assumptions
A3: Demand shift applied to a single product (share of its market; negative = replacement)
A4: Shift | C4: -0.1
A6: Animal supply elasticities
A7: Animal | B7: Sheet | C7: Short run | D7: Long run | E7: Source and range
A8: Dairy cow | B8: Dairy | C8: 0.12 | D8: 0.9 | E8: [S] Chavas & Klemme 1986: 0.115 (current year), 0.89 (5-year), 2.46 (10-year); EU medium-run 0.18-0.65 (Bouamra-Mechemache et al. 2005)
A9: Fed steer | B9: Beef | C9: 0.15 | D9: 0.8 | E9: [S] Wohlgenant 1993 beef supply 0.15 (SR); Lusk & Norwood 2009 LR 0.82; Harrington & Dubman 2008: 1.07
A10: Layer hen | B10: Eggs | C10: 0.03 | D10: 1 | E10: [S] Chavas 1980 SR 0.03; Chavas & Johnson 1981 LR ~1; Harrington & Dubman 2008: 1.04
A11: Broiler | B11: Broiler | C11: 0.1 | D11: 0.7 | E11: [S] Kapombe & Colyer 1998 SR 0.07 / LR 0.13; Chavas & Johnson 1982 0.02; Lusk & Norwood 2009 LR 0.70; Harrington & Dubman 1.15
A12: Hog | B12: Pork | C12: 0.4 | D12: 1.5 | E12: [S] Wohlgenant 1993 hog supply 0.40 (SR); Lusk & Norwood 2009 LR 1.56; Harrington & Dubman 0.79
A13: Alaska pollock | B13: Pollock | C13: 0 | D13: 0.05 | E13: [S] quota-managed capture: supply elasticity ~0 (World Bank 2013; estimates 0 to 0.17; can be negative)
A14: Farmed Atlantic salmon | B14: Salmon | C14: 0.1 | D14: 0.8 | E14: [S] Asheim et al. 2011 SR 0.09 / LR 0.14; Steen et al. 1997 LR 1.4-1.6; licences cap Norwegian biomass
A16: Short run = within a production cycle (months to ~1 year); long run = after herd/flock/capacity adjustment (3-5 years). Milk at a 10-year horizon: 2.5 (Chavas & Klemme). Wild capture under quota: ~0 at any horizon.

Sheet Dairy
A1: Dairy cow (2026 prices)
A2: Unit of analysis: per 100 lb milk + pro-rata cattle sales
A3: Structure: Milk is fungible across routes; cheese and whey are joint in fixed proportions; whey outlets are fungible.
A4: Prices: USDA AMS announced class prices Sep 2026 (Class I Oct 2026 advance); Dairy Market News Oct 2026 for whey products
A5: Supply elasticity sources: [S] Chavas & Klemme 1986: 0.115 (current year), 0.89 (5-year), 2.46 (10-year); EU medium-run 0.18-0.65 (Bouamra-Mechemache et al. 2005)
A7: Animal supply elasticity, short run (eps_s SR) | B7: =Assumptions!$C$8 -> 0.12
A8: Animal supply elasticity, long run (eps_s LR) | B8: =Assumptions!$D$8 -> 0.9
A9: Demand shift applied to one product at a time (share of its market, negative = replacement) | B9: =Assumptions!$C$4 -> -0.1
A11: Inputs (two price scenarios; select 1 = 2026, 2 = 2019-21 in the yellow cell). Values in blue are editable.
A12: Scenario selector (1 = 2026 prices, 2 = 2019-21 prices) | B12: 1
A13: Input | B13: Live value (used by the model) | C13: Scenario 1: 2026 | D13: Scenario 2: 2019-21 | E13: Unit | F13: Source / note
A14: Milk to fluid use (share of raw milk) | B14: =INDEX(C14:D14,1,$B$12) -> 0.19 | C14: 0.19 | D14: 0.19 | E14: share | F14: [E] NASS fluid sales ~43 bn lb of 232 bn lb
A15: Milk to cheese (share) | B15: =INDEX(C15:D15,1,$B$12) -> 0.6 | C15: 0.6 | D15: 0.6 | E15: share | F15: [E] 14.8 bn lb cheese / 10.6 lb per cwt / 232 bn lb
A16: Milk to butter and powder (share) | B16: =INDEX(C16:D16,1,$B$12) -> 0.13 | C16: 0.13 | D16: 0.13 | E16: share | F16: [E] residual
A17: Milk to other manufactured products (share) | B17: =INDEX(C17:D17,1,$B$12) -> 0.08 | C17: 0.08 | D17: 0.08 | E17: share | F17: [E] yogurt, ice cream, etc.
A18: Cheddar yield | B18: =INDEX(C18:D18,1,$B$12) -> 10.6 | C18: 10.6 | D18: 10.6 | E18: lb per cwt | F18: [S] Hoard's/CoBank (2020 composition; 11.6 in 2025)
A19: Whey solids | B19: =INDEX(C19:D19,1,$B$12) -> 6 | C19: 6 | D19: 5.9 | E19: lb per cwt cheese milk | F19: [S] FMMO other-solids factor
A20: Protein share of whey solids | B20: =INDEX(C20:D20,1,$B$12) -> 0.13 | C20: 0.13 | D20: 0.13 | E20: share | F20: [S] 0.8% protein in 6.5% solids whey
A21: Share of whey protein recovered into WPC/WPI | B21: =INDEX(C21:D21,1,$B$12) -> 0.5 | C21: 0.5 | D21: 0.5 | E21: share | F21: [E] NASS 2025 WPC+WPI protein vs liquid whey protein
A22: Of recovered whey protein, share going to WPC(50-90%) (rest WPI), protein basis | B22: =INDEX(C22:D22,1,$B$12) -> 0.61 | C22: 0.61 | D22: 0.61 | E22: share | F22: [S] NASS 2025: 381 m lb WPC x 0.8 vs 214 m lb WPI x 0.9
A23: Whey solids sold as dry whey (share) | B23: =INDEX(C23:D23,1,$B$12) -> 0.1 | C23: 0.1 | D23: 0.1 | E23: share | F23: [E] 845 m lb / ~8.4 bn lb solids
A24: Whey solids sold as lactose (share) | B24: =INDEX(C24:D24,1,$B$12) -> 0.15 | C24: 0.15 | D24: 0.15 | E24: share | F24: [E] 1,137 m lb
A25: Whey solids to permeate / condensed / feed (share) | B25: =INDEX(C25:D25,1,$B$12) -> 0.25 | C25: 0.25 | D25: 0.25 | E25: share | F25: [E] remainder not recovered as food products
... A43: Cull cows share of cattle sales (rest calves) | B43: =INDEX(C43:D43,1,$B$12) -> 0.6 | C43: 0.6 | D43: 0.6 | E43: share | F43: [E]
A45: Helper: milk value per cwt (sum of milk products, computed below) | B45: =SUM(H49:H58) -> 18.96644
A47: A. Products of one unit of the animal (sub-products). Blue = editable inputs; black = formulas.
A48: Sub-product | B48: Stream (fixed proportion within route) | C48: Route (fungible use of the raw commodity, or fixed to the animal) | D48: Quantity per unit | E48: Quantity unit | F48: Price | G48: Price unit | H48: Value | I48: Share of animal value | J48: Protein content (share of mass) | K48: w: share within stream | L48: DF short run (within a year) | M48: DF long run (3-5 years) | N48: DF constant-cost limit (supply perfectly elastic) | O48: DF LR, all-fixed variant | P48: DF LR, all-fungible variant | Q48: Stream price change for the shift in col. B9 | R48: Farm (animal) price change for that shift | S48: Shift at which stream hits its floor (as % of this product) | T48: Animal change if this product is fully replaced (LR, floor-capped, linear) | U48: kg animal unit displaced per kg product (LR) | V48: kg animal unit per kg protein replaced (LR) | W48: Source / note
A49: Fluid milk (Class I) | B49: Fluid milk | C49: Fluid | D49: =$B$14 -> 0.19 | F49: =$B$26 -> 18.88 | H49: =D49*F49 -> 3.5872 | I49: =H49/$H$61 -> 0.17438161 | J49: 0.033 | K49: =IF(SUMIF($B$49:$B$60,B49,$H$49:$H$60)=0,0,H49/SUMIF($B$49:$B$60,B49,$H$49:$H$60)) -> 1 | L49: =K49*INDEX($L$65:$L$73,MATCH(B49,$A$65:$A$73,0)) -> 0.026935892 | M49: =K49*INDEX($M$65:$M$73,MATCH(B49,$A$65:$A$73,0)) -> 0.10128844 | N49: =K49*INDEX($N$65:$N$73,MATCH(B49,$A$65:$A$73,0)) -> 0.17605264 | O49: =K49*INDEX($O$65:$O$73,MATCH(B49,$A$65:$A$73,0)) -> 0.16098793 | P49: =K49*INDEX($P$65:$P$73,MATCH(B49,$A$65:$A$73,0)) -> 0.094277378 | Q49: =INDEX($Q$65:$Q$73,MATCH(B49,$A$65:$A$73,0))*K49*$B$9 -> -0.013420291 | R49: =INDEX($R$65:$R$73,MATCH(B49,$A$65:$A$73,0))*K49*$B$9 -> -0.011254271 | S49: =IF(INDEX($S$65:$S$73,MATCH(B49,$A$65:$A$73,0))="","no external floor",INDEX($S$65:$S$73,MATCH(B49,$A$65:$A$73,0))/K49) -> no external floor | T49: =INDEX($M$65:$M$73,MATCH(B49,$A$65:$A$73,0))*IF(INDEX($S$65:$S$73,MATCH(B49,$A$65:$A$73,0))="",-K49,MAX(-K49,INDEX($S$65:$S$73,MATCH(B49,$A$65:$A$73,0)))) -> -0.10128844 | U49: =IF(D49=0,"",M49/D49*100) -> 53.309705 | V49: =IF(OR(J49="",J49=0),"",U49/J49) -> 1615.4456 | W49: [S] Class I price
A50: Other dairy: yogurt, ice cream, etc. (Class II) | B50: Other dairy | C50: Other manufactured | D50: =$B$17 -> 0.08 | F50: =$B$27 -> 17.6 | H50: =D50*F50 -> 1.408 | I50: =H50/$H$61 -> 0.068445951 | J50: 0.04 | K50: =IF(SUMIF($B$49:$B$60,B50,$H$49:$H$60)=0,0,H50/SUMIF($B$49:$B$60,B50,$H$49:$H$60)) -> 1 | L50: =K50*INDEX($L$65:$L$73,MATCH(B50,$A$65:$A$73,0)) -> 0.011341428 | M50: =K50*INDEX($M$65:$M$73,MATCH(B50,$A$65:$A$73,0)) -> 0.042647764 | N50: =K50*INDEX($N$65:$N$73,MATCH(B50,$A$65:$A$73,0)) -> 0.074127425 | O50: =K50*INDEX($O$65:$O$73,MATCH(B50,$A$65:$A$73,0)) -> 0.02808393 | P50: =K50*INDEX($P$65:$P$73,MATCH(B50,$A$65:$A$73,0)) -> 0.037004502 | Q50: =INDEX($Q$65:$Q$73,MATCH(B50,$A$65:$A$73,0))*K50*$B$9 -> -0.0056506489 | R50: =INDEX($R$65:$R$73,MATCH(B50,$A$65:$A$73,0))*K50*$B$9 -> -0.0047386405 | S50: =IF(INDEX($S$65:$S$73,MATCH(B50,$A$65:$A$73,0))="","no external floor",INDEX($S$65:$S$73,MATCH(B50,$A$65:$A$73,0))/K50) -> no external floor | T50: =INDEX($M$65:$M$73,MATCH(B50,$A$65:$A$73,0))*IF(INDEX($S$65:$S$73,MATCH(B50,$A$65:$A$73,0))="",-K50,MAX(-K50,INDEX($S$65:$S$73,MATCH(B50,$A$65:$A$73,0)))) -> -0.042647764 | U50: =IF(D50=0,"",M50/D50*100) -> 53.309705 | V50: =IF(OR(J50="",J50=0),"",U50/J50) -> 1332.7426 | W50: [S] Class II price
A51: Butter / cream (3.5 lb fat per cwt) | B51: Butter (fat) | C51: Butter & powder | D51: =$B$16 -> 0.13 | F51: =3.5*$B$29 -> 5.1667 | H51: =D51*F51 -> 0.671671 | I51: =H51/$H$61 -> 0.032651392 | J51: 0.005 | K51: =IF(SUMIF($B$49:$B$60,B51,$H$49:$H$60)=0,0,H51/SUMIF($B$49:$B$60,B51,$H$49:$H$60)) -> 1 | L51: =K51*INDEX($L$65:$L$73,MATCH(B51,$A$65:$A$73,0)) -> 0.0070910188 | M51: =K51*INDEX($M$65:$M$73,MATCH(B51,$A$65:$A$73,0)) -> 0.026664727 | N51: =K51*INDEX($N$65:$N$73,MATCH(B51,$A$65:$A$73,0)) -> 0.046346804 | O51: =K51*INDEX($O$65:$O$73,MATCH(B51,$A$65:$A$73,0)) -> 0.020095697 | P51: =K51*INDEX($P$65:$P$73,MATCH(B51,$A$65:$A$73,0)) -> 0.017652593 | Q51: =INDEX($Q$65:$Q$73,MATCH(B51,$A$65:$A$73,0))*K51*$B$9 -> -0.1075224 | R51: =INDEX($R$65:$R$73,MATCH(B51,$A$65:$A$73,0))*K51*$B$9 -> -0.0029627475 | S51: =IF(INDEX($S$65:$S$73,MATCH(B51,$A$65:$A$73,0))="","no external floor",INDEX($S$65:$S$73,MATCH(B51,$A$65:$A$73,0))/K51) -> no external floor | T51: =INDEX($M$65:$M$73,MATCH(B51,$A$65:$A$73,0))*IF(INDEX($S$65:$S$73,MATCH(B51,$A$65:$A$73,0))="",-K51,MAX(-K51,INDEX($S$65:$S$73,MATCH(B51,$A$65:$A$73,0)))) -> -0.026664727 | U51: =IF(D51=0,"",M51/D51*100) -> 20.511329 | V51: =IF(OR(J51="",J51=0),"",U51/J51) -> 4102.2658 | W51: [S] FMMO butterfat price x 3.5
A52: Nonfat dry milk / SMP (also the casein route) | B52: Milk powder (nonfat solids) | C52: Butter & powder | D52: =$B$16 -> 0.13 | F52: =9.3*0.965*$B$30 -> 13.769575 | H52: =D52*F52 -> 1.7900448 | I52: =H52/$H$61 -> 0.087017981 | J52: 0.36 | K52: =IF(SUMIF($B$49:$B$60,B52,$H$49:$H$60)=0,0,H52/SUMIF($B$49:$B$60,B52,$H$49:$H$60)) -> 1 | L52: =K52*INDEX($L$65:$L$73,MATCH(B52,$A$65:$A$73,0)) -> 0.011338802 | M52: =K52*INDEX($M$65:$M$73,MATCH(B52,$A$65:$A$73,0)) -> 0.04263789 | N52: =K52*INDEX($N$65:$N$73,MATCH(B52,$A$65:$A$73,0)) -> 0.074110262 | O52: =K52*INDEX($O$65:$O$73,MATCH(B52,$A$65:$A$73,0)) -> 0.032133766 | P52: =K52*INDEX($P$65:$P$73,MATCH(B52,$A$65:$A$73,0)) -> 0.047045253 | Q52: =INDEX($Q$65:$Q$73,MATCH(B52,$A$65:$A$73,0))*K52*$B$9 -> -0.043255676 | R52: =INDEX($R$65:$R$73,MATCH(B52,$A$65:$A$73,0))*K52*$B$9 -> -0.0047375433 | S52: =IF(INDEX($S$65:$S$73,MATCH(B52,$A$65:$A$73,0))="","no external floor",INDEX($S$65:$S$73,MATCH(B52,$A$65:$A$73,0))/K52) -> -0.69301141 | T52: =INDEX($M$65:$M$73,MATCH(B52,$A$65:$A$73,0))*IF(INDEX($S$65:$S$73,MATCH(B52,$A$65:$A$73,0))="",-K52,MAX(-K52,INDEX($S$65:$S$73,MATCH(B52,$A$65:$A$73,0)))) -> -0.029548544 | U52: =IF(D52=0,"",M52/D52*100) -> 32.798377 | V52: =IF(OR(J52="",J52=0),"",U52/J52) -> 91.106602 | W52: [S] FMMO nonfat solids price x 9.3 x 0.965
A53: Cheese (cheddar-equivalent) | B53: Cheese | C53: Cheese route | D53: =$B$15*$B$18 -> 6.36 | F53: =$B$28-$B$36 -> 1.3058 | H53: =D53*F53 -> 8.304888 | I53: =H53/$H$61 -> 0.40371872 | J53: 0.25 | K53: =IF(SUMIF($B$49:$B$60,B53,$H$49:$H$60)=0,0,H53/SUMIF($B$49:$B$60,B53,$H$49:$H$60)) -> 1 | L53: =K53*INDEX($L$65:$L$73,MATCH(B53,$A$65:$A$73,0)) -> 0.074960437 | M53: =K53*INDEX($M$65:$M$73,MATCH(B53,$A$65:$A$73,0)) -> 0.28187764 | N53: =K53*INDEX($N$65:$N$73,MATCH(B53,$A$65:$A$73,0)) -> 0.48994042 | O53: =K53*INDEX($O$65:$O$73,MATCH(B53,$A$65:$A$73,0)) -> 0.27106211 | P53: =K53*INDEX($P$65:$P$73,MATCH(B53,$A$65:$A$73,0)) -> 0.2182658 | Q53: =INDEX($Q$65:$Q$73,MATCH(B53,$A$65:$A$73,0))*K53*$B$9 -> -0.067202523 | R53: =INDEX($R$65:$R$73,MATCH(B53,$A$65:$A$73,0))*K53*$B$9 -> -0.031319738 | S53: =IF(INDEX($S$65:$S$73,MATCH(B53,$A$65:$A$73,0))="","no external floor",INDEX($S$65:$S$73,MATCH(B53,$A$65:$A$73,0))/K53) -> no external floor | T53: =INDEX($M$65:$M$73,MATCH(B53,$A$65:$A$73,0))*IF(INDEX($S$65:$S$73,MATCH(B53,$A$65:$A$73,0))="",-K53,MAX(-K53,INDEX($S$65:$S$73,MATCH(B53,$A$65:$A$73,0)))) -> -0.28187764 | U53: =IF(D53=0,"",M53/D53*100) -> 4.4320384 | V53: =IF(OR(J53="",J53=0),"",U53/J53) -> 17.728153 | W53: [S] cheese price less make allowance
A54: WPC 80 (whey protein concentrate) | B54: Whey protein | C54: Cheese route | D54: =$B$15*$B$19*$B$20*$B$21*$B$22/0.8 -> 0.178425 | F54: =$B$31-$B$39 -> 8 | H54: =D54*F54 -> 1.4274 | I54: =H54/$H$61 -> 0.069389027 | J54: 0.8 | K54: =IF(SUMIF($B$49:$B$60,B54,$H$49:$H$60)=0,0,H54/SUMIF($B$49:$B$60,B54,$H$49:$H$60)) -> 0.55037594 | L54: =K54*INDEX($L$65:$L$73,MATCH(B54,$A$65:$A$73,0)) -> 0.0047240605 | M54: =K54*INDEX($M$65:$M$73,MATCH(B54,$A$65:$A$73,0)) -> 0.017764131 | N54: =K54*INDEX($N$65:$N$73,MATCH(B54,$A$65:$A$73,0)) -> 0.030876397 | O54: =K54*INDEX($O$65:$O$73,MATCH(B54,$A$65:$A$73,0)) -> 0.017082529 | P54: =K54*INDEX($P$65:$P$73,MATCH(B54,$A$65:$A$73,0)) -> 0.037514365 | Q54: =INDEX($Q$65:$Q$73,MATCH(B54,$A$65:$A$73,0))*K54*$B$9 -> -0.034043237 | R54: =INDEX($R$65:$R$73,MATCH(B54,$A$65:$A$73,0))*K54*$B$9 -> -0.0019737923 | S54: =IF(INDEX($S$65:$S$73,MATCH(B54,$A$65:$A$73,0))="","no external floor",INDEX($S$65:$S$73,MATCH(B54,$A$65:$A$73,0))/K54) -> -1.7977098 | T54: =INDEX($M$65:$M$73,MATCH(B54,$A$65:$A$73,0))*IF(INDEX($S$65:$S$73,MATCH(B54,$A$65:$A$73,0))="",-K54,MAX(-K54,INDEX($S$65:$S$73,MATCH(B54,$A$65:$A$73,0)))) -> -0.017764131 | U54: =IF(D54=0,"",M54/D54*100) -> 9.9560774 | V54: =IF(OR(J54="",J54=0),"",U54/J54) -> 12.445097 | W54: [S] price; [A] processing allowance
A55: WPI (whey protein isolate) | B55: Whey protein | C55: Cheese route | D55: =$B$15*$B$19*$B$20*$B$21*(1-$B$22)/0.9 -> 0.1014 | F55: =$B$32-$B$40 -> 11.5 | H55: =D55*F55 -> 1.1661 | I55: =H55/$H$61 -> 0.056686664 | J55: 0.9 | K55: =IF(SUMIF($B$49:$B$60,B55,$H$49:$H$60)=0,0,H55/SUMIF($B$49:$B$60,B55,$H$49:$H$60)) -> 0.44962406 | L55: =K55*INDEX($L$65:$L$73,MATCH(B55,$A$65:$A$73,0)) -> 0.0038592735 | M55: =K55*INDEX($M$65:$M$73,MATCH(B55,$A$65:$A$73,0)) -> 0.014512227 | N55: =K55*INDEX($N$65:$N$73,MATCH(B55,$A$65:$A$73,0)) -> 0.02522416 | O55: =K55*INDEX($O$65:$O$73,MATCH(B55,$A$65:$A$73,0)) -> 0.013955399 | P55: =K55*INDEX($P$65:$P$73,MATCH(B55,$A$65:$A$73,0)) -> 0.030646981 | Q55: =INDEX($Q$65:$Q$73,MATCH(B55,$A$65:$A$73,0))*K55*$B$9 -> -0.027811278 | R55: =INDEX($R$65:$R$73,MATCH(B55,$A$65:$A$73,0))*K55*$B$9 -> -0.0016124697 | S55: =IF(INDEX($S$65:$S$73,MATCH(B55,$A$65:$A$73,0))="","no external floor",INDEX($S$65:$S$73,MATCH(B55,$A$65:$A$73,0))/K55) -> -2.2005411 | T55: =INDEX($M$65:$M$73,MATCH(B55,$A$65:$A$73,0))*IF(INDEX($S$65:$S$73,MATCH(B55,$A$65:$A$73,0))="",-K55,MAX(-K55,INDEX($S$65:$S$73,MATCH(B55,$A$65:$A$73,0)))) -> -0.014512227 | U55: =IF(D55=0,"",M55/D55*100) -> 14.311861 | V55: =IF(OR(J55="",J55=0),"",U55/J55) -> 15.902068 | W55: [S] price; [A] processing allowance
A56: Dry whey (sweet whey powder) | B56: Whey carbohydrate | C56: Cheese route | D56: =$B$15*$B$19*$B$23 -> 0.36 | F56: =$B$33-$B$37 -> 0.4026 | H56: =D56*F56 -> 0.144936 | I56: =H56/$H$61 -> 0.007045655 | J56: 0.12 | K56: =IF(SUMIF($B$49:$B$60,B56,$H$49:$H$60)=0,0,H56/SUMIF($B$49:$B$60,B56,$H$49:$H$60)) -> 0.23715834 | L56: =K56*INDEX($L$65:$L$73,MATCH(B56,$A$65:$A$73,0)) -> 0.00035975538 | M56: =K56*INDEX($M$65:$M$73,MATCH(B56,$A$65:$A$73,0)) -> 0.0013528069 | N56: =K56*INDEX($N$65:$N$73,MATCH(B56,$A$65:$A$73,0)) -> 0.0023513564 | O56: =K56*INDEX($O$65:$O$73,MATCH(B56,$A$65:$A$73,0)) -> 0.0013009003 | P56: =K56*INDEX($P$65:$P$73,MATCH(B56,$A$65:$A$73,0)) -> 0.0038091509 | Q56: =INDEX($Q$65:$Q$73,MATCH(B56,$A$65:$A$73,0))*K56*$B$9 -> -0.011706647 | R56: =INDEX($R$65:$R$73,MATCH(B56,$A$65:$A$73,0))*K56*$B$9 -> -0.00015031188 | S56: =IF(INDEX($S$65:$S$73,MATCH(B56,$A$65:$A$73,0))="","no external floor",INDEX($S$65:$S$73,MATCH(B56,$A$65:$A$73,0))/K56) -> -3.1811592 | T56: =INDEX($M$65:$M$73,MATCH(B56,$A$65:$A$73,0))*IF(INDEX($S$65:$S$73,MATCH(B56,$A$65:$A$73,0))="",-K56,MAX(-K56,INDEX($S$65:$S$73,MATCH(B56,$A$65:$A$73,0)))) -> -0.0013528069 | U56: =IF(D56=0,"",M56/D56*100) -> 0.3757797 | V56: =IF(OR(J56="",J56=0),"",U56/J56) -> 3.1314975 | W56: [S] price and make allowance
A57: Lactose | B57: Whey carbohydrate | C57: Cheese route | D57: =$B$15*$B$19*$B$24 -> 0.54 | F57: =$B$34-$B$38 -> 0.43 | H57: =D57*F57 -> 0.2322 | I57: =H57/$H$61 -> 0.011287748 | J57: 0 | K57: =IF(SUMIF($B$49:$B$60,B57,$H$49:$H$60)=0,0,H57/SUMIF($B$49:$B$60,B57,$H$49:$H$60)) -> 0.37994816 | L57: =K57*INDEX($L$65:$L$73,MATCH(B57,$A$65:$A$73,0)) -> 0.00057635921 | M57: =K57*INDEX($M$65:$M$73,MATCH(B57,$A$65:$A$73,0)) -> 0.0021673136 | N57: =K57*INDEX($N$65:$N$73,MATCH(B57,$A$65:$A$73,0)) -> 0.0037670762 | O57: =K57*INDEX($O$65:$O$73,MATCH(B57,$A$65:$A$73,0)) -> 0.0020841547 | P57: =K57*INDEX($P$65:$P$73,MATCH(B57,$A$65:$A$73,0)) -> 0.006102589 | Q57: =INDEX($Q$65:$Q$73,MATCH(B57,$A$65:$A$73,0))*K57*$B$9 -> -0.018755061 | R57: =INDEX($R$65:$R$73,MATCH(B57,$A$65:$A$73,0))*K57*$B$9 -> -0.00024081262 | S57: =IF(INDEX($S$65:$S$73,MATCH(B57,$A$65:$A$73,0))="","no external floor",INDEX($S$65:$S$73,MATCH(B57,$A$65:$A$73,0))/K57) -> -1.9856352 | T57: =INDEX($M$65:$M$73,MATCH(B57,$A$65:$A$73,0))*IF(INDEX($S$65:$S$73,MATCH(B57,$A$65:$A$73,0))="",-K57,MAX(-K57,INDEX($S$65:$S$73,MATCH(B57,$A$65:$A$73,0)))) -> -0.0021673136 | U57: =IF(D57=0,"",M57/D57*100) -> 0.40135437 | V57: =IF(OR(J57="",J57=0),"",U57/J57) | W57: [S] price; [A] allowance
A58: Permeate / condensed whey / feed | B58: Whey carbohydrate | C58: Cheese route | D58: =$B$15*$B$19*$B$25 -> 0.9 | F58: =$B$35-$B$41 -> 0.26 | H58: =D58*F58 -> 0.234 | I58: =H58/$H$61 -> 0.01137525 | J58: 0.04 | K58: =IF(SUMIF($B$49:$B$60,B58,$H$49:$H$60)=0,0,H58/SUMIF($B$49:$B$60,B58,$H$49:$H$60)) -> 0.3828935 | L58: =K58*INDEX($L$65:$L$73,MATCH(B58,$A$65:$A$73,0)) -> 0.00058082711 | M58: =K58*INDEX($M$65:$M$73,MATCH(B58,$A$65:$A$73,0)) -> 0.0021841145 | N58: =K58*INDEX($N$65:$N$73,MATCH(B58,$A$65:$A$73,0)) -> 0.0037962783 | O58: =K58*INDEX($O$65:$O$73,MATCH(B58,$A$65:$A$73,0)) -> 0.0021003109 | P58: =K58*INDEX($P$65:$P$73,MATCH(B58,$A$65:$A$73,0)) -> 0.0061498959 | Q58: =INDEX($Q$65:$Q$73,MATCH(B58,$A$65:$A$73,0))*K58*$B$9 -> -0.018900449 | R58: =INDEX($R$65:$R$73,MATCH(B58,$A$65:$A$73,0))*K58*$B$9 -> -0.00024267939 | S58: =IF(INDEX($S$65:$S$73,MATCH(B58,$A$65:$A$73,0))="","no external floor",INDEX($S$65:$S$73,MATCH(B58,$A$65:$A$73,0))/K58) -> -1.9703611 | T58: =INDEX($M$65:$M$73,MATCH(B58,$A$65:$A$73,0))*IF(INDEX($S$65:$S$73,MATCH(B58,$A$65:$A$73,0))="",-K58,MAX(-K58,INDEX($S$65:$S$73,MATCH(B58,$A$65:$A$73,0)))) -> -0.0021841145 | U58: =IF(D58=0,"",M58/D58*100) -> 0.24267939 | V58: =IF(OR(J58="",J58=0),"",U58/J58) -> 6.0669847 | W58: [S] feed-grade whey price
A59: Cull cows (manufacturing beef) | B59: Cull cows | C59: Cattle sales | D59: =1 -> 1 | F59: =$B$45*$B$42/(1-$B$42)*$B$43 -> 0.96272167 | H59: =D59*F59 -> 0.96272167 | I59: =H59/$H$61 -> 0.0468 | J59: 0.18 | K59: =IF(SUMIF($B$49:$B$60,B59,$H$49:$H$60)=0,0,H59/SUMIF($B$49:$B$60,B59,$H$49:$H$60)) -> 1 | L59: =K59*INDEX($L$65:$L$73,MATCH(B59,$A$65:$A$73,0)) -> 0.0059459464 | M59: =K59*INDEX($M$65:$M$73,MATCH(B59,$A$65:$A$73,0)) -> 0.022358852 | N59: =K59*INDEX($N$65:$N$73,MATCH(B59,$A$65:$A$73,0)) -> 0.038862627 | O59: =K59*INDEX($O$65:$O$73,MATCH(B59,$A$65:$A$73,0)) -> 0.021602723 | P59: =K59*INDEX($P$65:$P$73,MATCH(B59,$A$65:$A$73,0)) -> 0.025301872 | Q59: =INDEX($Q$65:$Q$73,MATCH(B59,$A$65:$A$73,0))*K59*$B$9 -> -0.12220514 | R59: =INDEX($R$65:$R$73,MATCH(B59,$A$65:$A$73,0))*K59*$B$9 -> -0.0024843169 | S59: =IF(INDEX($S$65:$S$73,MATCH(B59,$A$65:$A$73,0))="","no external floor",INDEX($S$65:$S$73,MATCH(B59,$A$65:$A$73,0))/K59) -> -0.78826208 | T59: =INDEX($M$65:$M$73,MATCH(B59,$A$65:$A$73,0))*IF(INDEX($S$65:$S$73,MATCH(B59,$A$65:$A$73,0))="",-K59,MAX(-K59,INDEX($S$65:$S$73,MATCH(B59,$A$65:$A$73,0)))) -> -0.017624635 | U59: =IF(D59=0,"",M59/D59*100) -> 2.2358852 | V59: =IF(OR(J59="",J59=0),"",U59/J59) -> 12.421585 | W59: [S] ERS cattle sales share; [E] 60/40 split
A60: Calves (beef-on-dairy, bull calves) | B60: Calves | C60: Cattle sales | D60: =1 -> 1 | F60: =$B$45*$B$42/(1-$B$42)*(1-$B$43) -> 0.64181445 | H60: =D60*F60 -> 0.64181445 | I60: =H60/$H$61 -> 0.0312 | J60: 0.18 | K60: =IF(SUMIF($B$49:$B$60,B60,$H$49:$H$60)=0,0,H60/SUMIF($B$49:$B$60,B60,$H$49:$H$60)) -> 1 | L60: =K60*INDEX($L$65:$L$73,MATCH(B60,$A$65:$A$73,0)) -> 0.0052852857 | M60: =K60*INDEX($M$65:$M$73,MATCH(B60,$A$65:$A$73,0)) -> 0.019874535 | N60: =K60*INDEX($N$65:$N$73,MATCH(B60,$A$65:$A$73,0)) -> 0.034544557 | O60: =K60*INDEX($O$65:$O$73,MATCH(B60,$A$65:$A$73,0)) -> 0.01920242 | P60: =K60*INDEX($P$65:$P$73,MATCH(B60,$A$65:$A$73,0)) -> 0.016867915 | Q60: =INDEX($Q$65:$Q$73,MATCH(B60,$A$65:$A$73,0))*K60*$B$9 -> -0.16335424 | R60: =INDEX($R$65:$R$73,MATCH(B60,$A$65:$A$73,0))*K60*$B$9 -> -0.0022082817 | S60: =IF(INDEX($S$65:$S$73,MATCH(B60,$A$65:$A$73,0))="","no external floor",INDEX($S$65:$S$73,MATCH(B60,$A$65:$A$73,0))/K60) -> -0.84020875 | T60: =INDEX($M$65:$M$73,MATCH(B60,$A$65:$A$73,0))*IF(INDEX($S$65:$S$73,MATCH(B60,$A$65:$A$73,0))="",-K60,MAX(-K60,INDEX($S$65:$S$73,MATCH(B60,$A$65:$A$73,0)))) -> -0.016698759 | U60: =IF(D60=0,"",M60/D60*100) -> 1.9874535 | V60: =IF(OR(J60="",J60=0),"",U60/J60) -> 11.041409 | W60: [E]
A61: Total value of one unit of the animal | H61: =SUM(H49:H60) -> 20.570976 | I61: =SUM(I49:I60) -> 1
...

Sheet Beef
A1: Fed steer (Oct 2026 prices)
A2: Unit of analysis: per 1,400 lb Choice steer
A3: Structure: Carcass cuts in fixed proportions (one route); grinding is a one-way re-route handled as a floor on whole-cut streams in the text.
A4: Prices: USDA AMS boxed beef cutout 15 Oct 2026; by-product drop value 15 Oct 2026
A5: Supply elasticity sources: [S] Wohlgenant 1993 beef supply 0.15 (SR); Lusk & Norwood 2009 LR 0.82; Harrington & Dubman 2008: 1.07
A7: Animal supply elasticity, short run (eps_s SR) | B7: =Assumptions!$C$9 -> 0.15
A8: Animal supply elasticity, long run (eps_s LR) | B8: =Assumptions!$D$9 -> 0.8
A9: Demand shift applied to one product at a time (share of its market, negative = replacement) | B9: =Assumptions!$C$4 -> -0.1
A11: Inputs: carcass yields, primal values, drop credit (blue = editable)
A12: Input | B12: Value | C12: Unit | D12: Source / note
A13: Live weight | B13: 1400 | C13: lb | D13: [S] AMS drop report: typical steer 1,400 lb
A14: Dressing percentage | B14: 0.63 | C14: share | D14: [S] AMS 63.0%
A15: Rib yield (share of carcass) | B15: 0.114 | C15: share | D15: [S] AMS cutout yield factors
A16: Rib primal value | B16: 6.7612 | C16: $/lb | D16: [S] AMS 15 Oct 2026 Choice
A17: Chuck yield | B17: 0.2962 | C17: share | D17: [S]
A18: Chuck primal value | B18: 3.374 | C18: $/lb | D18: [S]
A19: Round yield | B19: 0.2232 | C19: share | D19: [S]
A20: Round primal value | B20: 2.9522 | C20: $/lb | D20: [S]
A21: Loin yield | B21: 0.2126 | C21: share | D21: [S]
A22: Loin primal value | B22: 4.5003 | C22: $/lb | D22: [S]
A23: Brisket yield | B23: 0.0495 | C23: share | D23: [S]
A24: Brisket primal value | B24: 2.8783 | C24: $/lb | D24: [S]
... A38: Drop value: meat & bone meal + blood meal | B38: 1.38 | C38: $/cwt live | D38: [S]
A40: A. Products of one unit of the animal (sub-products). Blue = editable inputs; black = formulas.
A41: Sub-product | B41: Stream (fixed proportion within route) | C41: Route (fungible use of the raw commodity, or fixed to the animal) | D41: Quantity per unit | E41: Quantity unit | F41: Price | G41: Price unit | H41: Value | I41: Share of animal value | J41: Protein content (share of mass) | K41: w: share within stream | L41: DF short run (within a year) | M41: DF long run (3-5 years) | N41: DF constant-cost limit (supply perfectly elastic) | O41: DF LR, all-fixed variant | P41: DF LR, all-fungible variant | Q41: Stream price change for the shift in col. B9 | R41: Farm (animal) price change for that shift | S41: Shift at which stream hits its floor (as % of this product) | T41: Animal change if this product is fully replaced (LR, floor-capped, linear) | U41: kg animal unit displaced per kg product (LR) | V41: kg animal unit per kg protein replaced (LR) | W41: Source / note
A42: Middle meats: steaks and roasts from rib and loin | B42: Middle meats (whole cut) | C42: Carcass | D42: =$B$13*$B$14*($B$15+$B$21) -> 288.0612 | F42: =($B$15*$B$16+$B$21*$B$22)/($B$15+$B$21) -> 5.289469 | H42: =D42*F42 -> 1523.6908 | I42: =H42/$H$50 -> 0.43407997 | J42: 0.2 | K42: =IF(SUMIF($B$42:$B$49,B42,$H$42:$H$49)=0,0,H42/SUMIF($B$42:$B$49,B42,$H$42:$H$49)) -> 1 | L42: =K42*INDEX($L$54:$L$57,MATCH(B42,$A$54:$A$57,0)) -> 0.056353981 | M42: =K42*INDEX($M$54:$M$57,MATCH(B42,$A$54:$A$57,0)) -> 0.18988031 | N42: =K42*INDEX($N$54:$N$57,MATCH(B42,$A$54:$A$57,0)) -> 0.41896718 | O42: =K42*INDEX($O$54:$O$57,MATCH(B42,$A$54:$A$57,0)) -> 0.18988031 | P42: =K42*INDEX($P$54:$P$57,MATCH(B42,$A$54:$A$57,0)) -> 0.19001109 | Q42: =INDEX($Q$54:$Q$57,MATCH(B42,$A$54:$A$57,0))*K42*$B$9 -> -0.081011969 | R42: =INDEX($R$54:$R$57,MATCH(B42,$A$54:$A$57,0))*K42*$B$9 -> -0.023735039 | S42: =IF(INDEX($S$54:$S$57,MATCH(B42,$A$54:$A$57,0))="","no external floor",INDEX($S$54:$S$57,MATCH(B42,$A$54:$A$57,0))/K42) -> no external floor | T42: =INDEX($M$54:$M$57,MATCH(B42,$A$54:$A$57,0))*IF(INDEX($S$54:$S$57,MATCH(B42,$A$54:$A$57,0))="",-K42,MAX(-K42,INDEX($S$54:$S$57,MATCH(B42,$A$54:$A$57,0)))) -> -0.18988031 | U42: =IF(D42=0,"",M42/D42*1400) -> 0.92283317 | V42: =IF(OR(J42="",J42=0),"",U42/J42) -> 4.6141659 | W42: [S] AMS primals
